Workbook

Sheet 範型_苦情クレーム
A1: 第1カタログ 範型 ── 発語内行為「苦情・クレーム（Complaining）」
A2: 類型：指示的（directive）＋表出的要素 ／ 本質：相手（店・機関・個人）に、現状が期待に反することを伝え、是正を求める。非難と要求の二面を持ち、両者のバランスが行為の成否を決める。
A4: モード | B4: レベル | C4: No. | D4: CEFR記述文（原文） | E4: 記述文（作業訳） | F4: 実例（exponent） | G4: 場面 | H4: 効くhow well軸 | I4: 日本語話者へのL1語用論注意 | J4: 隣接レベルとの差分
A5: 口頭 | B5: A2 | C5: 544 | D5: Can point out when something is wrong (e.g. “The food is cold” or “There is no light in my room”). | E5: 何かがおかしいときに指摘できる（「料理が冷たい」「部屋の電気がつかない」など）。 | F5: • Excuse me, the food is cold. • Sorry, there is no light in my room. • Excuse me, this is not what I ordered. | G5: レストランやホテルで、出されたもの・状態が違うとき、その事実を一言告げる。 | H5: 社会言語的適切さ（最小）：Excuse me / Sorry を頭に置けるか。 | I5: 日本語話者は「事実の指摘」を非難と感じて言い出せない傾向。英語では The food is cold. と現状を述べること自体は失礼でなく、むしろ必要な情報提供。黙って我慢する方が不自然。ただし頭に Excuse me を欠くと唐突。 | J5: （起点）行為の最小形。まだ是正要求は含まず、問題の存在を告げるだけ。
A6: 口頭 | B6: B1 | C6: 533 | D6: Can make a complaint. | E6: 苦情を言える。 | F6: • Excuse me, I ordered the pasta but this is a pizza. Could you change it, please? • I'm sorry, but the room is really noisy. Would it be possible to move to another one? • There seems to be a problem with the bill — I think we've been charged twice. | G6: 注文違い・部屋の問題・請求の誤りなど、具体的な不都合について、是正を求めるところまで言う。 | H6: 社会言語的適切さ＋叙述の正確さ：問題の describe と要求の request を一続きにできるか。 | I6: 日本語の「すみません、これ頼んでないんですけど……」は語尾を濁して相手に察してもらう構造。英語では Could you change it? まで言い切らないと要求が伝わらず、問題提起だけで終わると「ただ不機嫌な人」になる。緩衝（I'm sorry but / There seems to be）＋明示的要求、の二点セットが鍵。 | J6: A2からの飛躍：問題の指摘に「是正の要求」が加わる。行為が完結する最初のレベル。
A7: 口頭 | B7: B1 | C7: 532 | D7: Can cope with less routine situations in shops, post offices, banks, e.g. returning an unsatisfactory purchase. | E7: 満足できない買い物の返品など、店・郵便局・銀行でのあまり日常的でない状況に対処できる。 | F7: • I bought this shirt yesterday, but there's a hole in the sleeve. I'd like to return it, please. • This isn't working properly — can I get a refund or an exchange? • I'd like to return this. Do you need the receipt? | G7: 店で不良品を返品する、想定外のやりとり（理由の説明・レシートの授受）に対応する。 | H7: 柔軟さ：相手の反応（レシートは？交換か返金か）に応じて言い足せるか。 | I7: 返品は日本でも増えたが、英語圏では「正当な権利の行使」であり、過度に低姿勢だと逆に不審。I'd like to return this と平叙で切り出してよい。「返品してもらえますか」を Can I possibly...? と過剰に婉曲化すると、かえって要領を得ない。 | J7: 同じB1でも、単発の苦情から「一連のやりとりへの対処」へ。相手の応答を捌く柔軟さが問われる。
A8: 口頭 | B8: B2+ | C8: 526 | D8: Can cope linguistically to negotiate a solution to a dispute like an undeserved traffic ticket, financial responsibility for damage in a flat, or blame regarding an accident. | E8: 不当な交通違反切符、住居の損傷の金銭的責任、事故の責めなど、争いの解決を交渉する言語的能力がある。 | F8: • I understand your position, but I don't think I'm liable for this. The damage was already there when I moved in. • I'd like to contest this. Could you tell me exactly which regulation I'm supposed to have broken? • I'm willing to cover part of it, but not the full amount — let me explain why. | G8: 責任の所在が争われる場面で、相手の主張を受けつつ自分の立場を通し、着地点を探る。 | H8: 叙述の正確さ＋柔軟さ＋社会言語的適切さ：反論しつつ関係を壊さない語調の制御。 | I8: 日本語話者は対立局面で沈黙するか、逆に感情的に強く出るかの両極に振れやすい。英語の交渉苦情は I understand X, but Y（相手の承認→自分の主張）という型が定石で、冷静に but でつなぐ。謝罪の I'm sorry を安易に挟むと責任を認めた含意になり不利。 | J8: 苦情から「交渉」へ。一方的要求ではなく、相手の立場の承認と自分の譲歩限度の提示が入る。
A9: 口頭 | B9: B2+ | C9: 527 | D9: Can outline a case for compensation, using persuasive language to demand satisfaction and state clearly the limits to any concession they are prepared to make. | E9: 説得力のある言葉で補償を求める主張を組み立て、満足を要求し、譲歩できる限度を明確に述べられる。 | F9: • Given the inconvenience caused, I believe a full refund plus compensation for the extra costs is reasonable. • I'm prepared to accept a replacement, but only if it's delivered by Friday — otherwise I'll expect a refund. • This has cost me two days of work. I'd like that reflected in whatever you're offering. | G9: 実害が生じた案件で、補償の根拠を筋道立てて示し、受け入れ条件と限度を明言する。 | H9: 叙述の正確さ（最大）＋話題の展開：根拠→要求→条件を論理的に積む構成力。 | I9: 「譲歩の限度を明示する」は日本語の交渉文化と最も遠い。日本語では限度をあえて曖昧にして含みで交渉するが、英語では but only if... / otherwise I'll... と条件と帰結を言語化するのが誠実で強い。曖昧なままだと足元を見られる。 | J9: 交渉に「論理的な根拠づけ」と「条件の明示的言語化」が加わる。口頭系列の到達点。
A10: 書面 | B10: B1+ | C10: 638 | D10: Can compose basic formal e-mails/letters (e.g. to make a complaint and request action). | E10: 基本的な公式のメールや手紙（苦情を述べ対応を求めるなど）を書ける。 | F10: • Dear Sir or Madam, I am writing to complain about the delayed delivery of my order (#12345). I would like to request a full refund. • I ordered the item on 3 May, but it has still not arrived. Please let me know how you intend to resolve this. | G10: 遅延・不良・誤請求について、公式メールで苦情と対応要求を伝える。 | H10: 社会言語的適切さ（書面レジスター）：I am writing to... の定型と Dear/Yours の枠を守れるか。 | I10: 日本語のビジネス苦情メールは長い前置き（お世話になっております＋クッション）から入るが、英語は I am writing to complain about... と冒頭で用件を明示するのが正しい作法。前置きを長くすると要領を得ない印象。 | J10: 口頭B1と並行して、書面系列が独立に立ち上がる。定型（I am writing to）とレジスターの獲得が核。
A11: 書面 | B11: B2+ | C11: 629 | D11: Can compose a forceful but polite letter of complaint, including supporting details and a statement of the desired outcome. | E11: 裏づけの詳細と望む結果を明記した、力強くも丁寧な苦情の手紙を書ける。 | F11: • Despite my email of 3 May, the issue remains unresolved. I have now been waiting three weeks for a replacement. • I trust you will appreciate my frustration and arrange a full refund within seven days. | G11: 一度目の苦情が解決されない案件で、経緯を裏づけつつ、丁寧さを保って強く要求する。 | H11: 話題の展開＋社会言語的適切さ：forceful と polite を両立させる語調設計。 | I11: 「力強くも丁寧に」の両立が難所。日本語話者は polite に振れすぎて要求が弱まるか、直訳的に強く書いて無礼になるか。英語は I trust you will... / I would appreciate it if... で、丁寧な形式のまま圧をかける定型がある。この「丁寧な強さ」の語彙庫を持つことが鍵。 | J11: 書面B1+からの飛躍：単発の苦情から、経緯の裏づけ・望む結果の明記・語調の制御へ。
A12: 書面 | B12: B2+ | C12: 628 | D12: Can compose formal correspondence such as letters of enquiry, request, application and complaint using appropriate register, structure and conventions. | E12: 適切な言語使用域・構成・慣習を使って、問い合わせ・依頼・応募・苦情などの公式の通信文を書ける。 | F12: • I am writing with reference to invoice #789, which appears to contain an error. • I would be grateful if you could look into this matter and respond at your earliest convenience. | G12: 苦情を含む各種公式通信を、型・レジスター・慣習に則って書き分ける。 | H12: 社会言語的適切さ（慣習の体系）：with reference to / at your earliest convenience 等の定型群の運用。 | I12: 英語の公式通信は定型表現の体系（with reference to, I would be grateful if, at your earliest convenience）で動く。日本語の敬語体系とは別物なので、日本語敬語を英語に写そうとせず、英語独自の formal 定型を丸ごと語彙として習得する必要がある。 | J12: 個別の苦情から「公式通信文一般の型」への一般化。苦情が他の書面行為（依頼・応募）と型を共有すると気づく段。
A13: 書面 | B13: C1 | C13: 625 | D13: Can, with good expression and accuracy, compose formal correspondence such as letters of clarification, application, recommendation, reference, complaint, sympathy and condolence. | E13: 明確化・応募・推薦・照会・苦情・見舞い・弔慰の手紙など、公式の通信文を、うまい表現と正確さで書ける。 | F13: • While I appreciate that delays can occur, a three-week silence following my formal complaint is difficult to justify. • I would ask that you treat this as a matter of urgency and confirm your proposed resolution in writing. | G13: 洗練を要する公式通信で、含意・語調・正確さを制御して苦情を述べる。 | H13: 叙述の正確さ＋柔軟さ（最大）：含意・皮肉・緩衝を精密に制御する表現力。 | I13: C1では While I appreciate that..., ... is difficult to justify のような、譲歩節で相手を立てつつ論理で追い込む高度な緩衝が要る。日本語の高等な苦情（慇懃な圧）に感覚は近いが、英語独自のレトリックなので、日本語の語感からの類推は危険。個別の表現を範例で覚える段階。 | J13: B2+からの到達点：正確さに加え「うまい表現（good expression）」＝含意と語調の精密制御。書面系列の頂点。
A15: DISCUSSION ── この行為をパターンとして読む（アレグザンダー式・行為全体への散文）
A16: 【緩衝（mitigation）が行為の背骨である】 英語の苦情を貫く原理は「非難性の緩衝」である。同じ事実（料理が冷たい）を、A2では Excuse me を頭に置くだけ、B1では There seems to be... で事実を非人称化し、B2+では I understand your position, but... で相手を立て、C1では While I appreciate that... と譲歩節で包む——レベルが上がるとは、緩衝の技法が精緻化することにほかならない。この行為において how well の主軸は一貫して社会言語的適切さであり、文法的正確さではない。文法的に完璧な The food is cold and I want a new one now. は、B1の緩衝された表現より「下手」なのである。 【日本語話者にとっての二重の壁】 第一の壁は「言い出せない」こと。日本語文化では苦情＝関係を損なう行為とされ、我慢が美徳になりやすい。だが英語圏では、正当な苦情は消費者の権利であり情報提供でもあって、黙る方が不自然に映る。第二の壁は、言い出せた場合に「振れすぎる」こと——過度に低姿勢で要求が伝わらないか、直訳的に強く出て無礼になるかの両極。英語の苦情は「丁寧な形式を保ったまま要求を明示する」ことを求めるが、これは日本語の「察してもらう」構造とも「けんか腰」とも異なる第三の様式であり、明示的に学ぶしかない。 【苦情は依頼と背中合わせである】 「部屋が寒い」（苦情）は「暖房を入れてほしい」（依頼）と表裏一体で、多くの苦情は是正の依頼を含意する。25行為インベントリで苦情と依頼を別立てにしたが、実運用では連続する。苦情を教えるとき、是正要求（依頼）まで一続きで示さないと、行為が完結しない——日本語話者が問題提起だけで止まりがちなのは、この連続性が母語で言語化されないためでもある。 【口頭と書面は別の行為に近い】 CEFRが苦情を口頭スケール（Obtaining goods and services）と書面スケール（Correspondence）に分けて記述しているのは示唆的である。口頭の苦情は即時・対面で、緩衝も即興的（Excuse me, sorry）。書面の苦情は経緯の裏づけ・構成・レジスターが前面に出て、定型表現の体系（I am writing to, I would be grateful if）で動く。学習者にとっては習得順序も異なり、口頭A2から始まる系列と、書面B1+から始まる系列は、並行して別々に登らせるのが自然である。 【なぜこの行為が範型に適するか】 苦情は、発語内行為25種の中でも、L1語用論的転移が最も激しく、かつレベル差分が最も明瞭に観察できる。緩衝技法の精緻化としてA2→C1が一直線に読め、how wellの主軸（社会言語的適切さ）が行為全体を貫く。他の24行為を作り込む際、この「緩衝の精緻化」「言い出せない／振れすぎるの二重の壁」「隣接行為との連続」「口頭・書面の分岐」という4つの観察軸が、そのまま点検リストになる。

Sheet 範型_挨拶別れ安否
A1: 第1カタログ 範型 ── 発語内行為「挨拶・別れ・安否（Greeting, Leave-taking & Phatic exchange）」
A2: 類型：交話的（phatic）── 情報伝達より関係の確立・維持が目的 ／ 本質：出会いと別れの区切りに定型表現を交わし、相手との社会的接触を開き・保ち・閉じる。内容の正しさより、型の適切さとテンポが行為の成否を決める。
A4: モード | B4: レベル | C4: No. | D4: CEFR記述文（原文） | E4: 記述文（作業訳） | F4: 実例（exponent） | G4: 場面 | H4: 効くhow well軸 | I4: 日本語話者へのL1語用論注意 | J4: 隣接レベルとの差分
A5: 口頭 | B5: Pre-A1 | C5: 453 | D5: Can understand and use basic, formulaic expressions such as “Yes”, “No”, “Excuse me”, “Please”, “Thank you”, “No thank you”, “Sorry”. | E5: 「はい」「いいえ」「すみません」「お願いします」「ありがとう」「けっこうです」「ごめんなさい」などの基本的な決まり文句を理解し、使える。 | F5: • Yes. / No. • Thank you. / No thank you. • Excuse me. / Sorry. • Please. | G5: あらゆる接触の潤滑油となる最小の定型語を、適切な場面で口にする。 | H5: 社会言語的適切さ（最小単位）：型を型として口に出せるか。 | I5: No thank you を「いいえ、結構です」の丁寧な断りとして使えず、単に No と言って冷たく響くことがある。また Sorry と Excuse me の使い分け（謝罪／呼びかけ・断り）が日本語の「すみません」に一括されるため混同しやすい。 | J5: （起点）語彙ですらなく「機能語の塊」。関係の潤滑油の最小部品。
A6: 口頭 | B6: Pre-A1 | C6: 455 | D6: Can greet people, state their name and take leave in a simple way. | E6: 挨拶し、名前を名乗り、簡単な方法で別れを告げられる。 | F6: • Hello. / Hi. • I'm Kenji. • Goodbye. / Bye. • See you. | G6: 初対面や店・受付で、挨拶し名乗り、辞去する。会話の開閉の枠。 | H6: 社会言語的適切さ：出会いと別れの型をペアで押さえられるか。 | I6: 別れ際の See you. や Bye. を言わずに立ち去る、あるいは Goodbye だけで済ませて素っ気なくなる。日本語の「じゃあ」「どうも」に当たる軽い辞去表現の層が薄い。 | J6: 定型語から「会話の開閉」へ。挨拶と別れは対で機能する。
A7: 口頭 | B7: A1 | C7: 451 | D7: Can make an introduction and use basic greeting and leave-taking expressions. | E7: 紹介をし、基本的な挨拶や別れの表現を使える。 | F7: • Good morning. / Good afternoon. • This is my friend, Aya. • Nice to meet you. • Have a nice day! | G7: 他者を紹介し、時間帯に応じた挨拶と、別れ際の一言を添える。 | H7: 社会言語的適切さ：時間帯・相手による型の選択。 | I7: Nice to meet you.（初対面）と Nice to see you.（再会）の別を知らず、再会でも meet を使ってしまう。Have a nice day! のような別れ際の「気遣いの一言」を添える習慣が乏しく、挨拶が短く切れる。 | J7: Pre-A1からの差分：時間帯別（morning/afternoon）と紹介（This is...）が加わり、型が場面分化する。
A8: 口頭 | B8: A1 | C8: 452 | D8: Can ask how people are and react to news. | E8: 人の調子を尋ね、知らせに反応できる。 | F8: • How are you? — Fine, thanks. And you? • How's it going? • That's great! / Oh, I'm sorry to hear that. | G8: 相手の近況・体調を尋ね、返ってきた知らせに感情で応じる。 | H8: 社会言語的適切さ＋テンポ：定型的な問い返し（And you?）の即応。 | I8: How are you? を「本当に体調を訊く質問」と受け取り、長々と実際の状態を答えてしまう。英語では儀礼的な往復（Fine, thanks. And you?）が基本で、中身より往復のテンポが大事。この phatic な性質が日本語話者に最も伝わりにくい。 | J8: 一方向の挨拶から「往復」へ。相手の応答に反応する対話性が入る。
A9: 口頭 | B9: A2 | C9: 444 | D9: Can use simple, everyday, polite forms of greeting and address. | E9: 簡単な日常の丁寧な挨拶や呼びかけの表現形式を使える。 | F9: • Good evening, Mr. Tanaka. • Excuse me, sir. / Excuse me, madam. • How do you do?（改まった初対面） | G9: 目上や公的な相手に、丁寧なレジスターで挨拶し呼びかける。 | H9: 社会言語的適切さ（レジスター）：親しさ／改まりで型を選び分けられるか。 | I9: 英語の呼びかけには sir/madam や Mr./Ms.＋姓があるが、日本語の「〜さん」を万能に使う感覚で first name を使い、目上に馴れ馴れしく響く。逆に過度に Mr. を連発して不自然になることも。相手との距離に応じた呼称選択は明示的な学習を要する。 | J9: A1からの差分：中立な挨拶から「丁寧なレジスター」の選択へ。呼びかけ（address）が加わる。
A10: 口頭 | B10: A2+ | C10: 438 | D10: Can establish social contact (e.g. greetings and farewells, introductions, giving thanks). | E10: 社交的接触（挨拶と別れ、紹介、感謝など）を確立できる。 | F10: • Hi, I don't think we've met — I'm Kenji. • It was really nice talking to you. • Thanks so much for having me. / Let's keep in touch. | G10: パーティや職場で、自ら関係を開き、会話を交わし、良い印象で閉じる一連。 | H10: 社会言語的適切さ＋柔軟さ：開始・維持・終了を状況に合わせて束ねる。 | I10: 関係を自分から「開く」定型（I don't think we've met）や、良い印象で「閉じる」定型（It was nice talking to you / keep in touch）の層が薄く、挨拶が入口だけで終わりがち。日本語では別れの挨拶が定型的に厚いのに、英語ではその機能表現を別途習得しないと使えない。 | J10: 個別の挨拶から「社交的接触の確立」へ。開始〜維持〜終了を一続きの営みとして統合する到達点。
A11: 書面 | B11: Pre-A1 | C11: 686 | D11: Can post simple online greetings, using basic formulaic expressions and emoticons. | E11: 基本的な決まり文句と絵文字を使って、簡単なオンラインの挨拶を投稿できる。 | F11: • Happy birthday! 🎉 • Good luck! 😊 • Congrats! | G11: SNSやチャットで、定型句＋絵文字の短い挨拶を投稿する。 | H11: 社会言語的適切さ（オンライン・レジスター）：くだけた場の型と絵文字の運用。 | I11: 日本語のオンライン儀礼（「おめでとう🎊」）の感覚は近いが、英語の Congrats! / Happy belated birthday!（遅れた誕生日祝い）のような口語省略形を知らず、硬い Congratulations に留まる。絵文字の使用も控えめすぎることがある。 | J11: （書面起点）口頭の定型語が、オンラインでは絵文字と結んで機能する。
A12: 書面 | B12: A1 | C12: 648 | D12: Can compose a short, simple postcard. | E12: 短く簡単なはがきを書ける。 | F12: • Dear Aya, Greetings from Kyoto! The temples are beautiful. See you soon, Kenji • Hi Mom, Having a great time here. Weather is lovely. Love, Kenji | G12: 旅先などから、近況の一言を添えた短いはがきを書く。 | H12: 社会言語的適切さ（書面枠）：Dear... と結び（Love/See you soon）の枠を守れるか。 | I12: はがき・手紙の結びの語（Love, / Best, / See you soon,）の層が薄く、日本語の「それでは」を直訳して不自然になる。宛名の Dear は日本語の「親愛なる」より軽く日常的、という温度感も掴みにくい。 | J12: オンライン挨拶からの差分：書面の「枠」（宛名・本文・結び）が加わる。
A13: 書面 | B13: A2 | C13: 682 | D13: Can engage in basic social communication online (e.g. a simple message on a virtual card for special occasions, sharing news and making/confirming arrangements to meet). | E13: オンラインで基本的な社交（特別な機会のカードへの一言、近況共有、会う約束の設定・確認など）ができる。 | F13: • Congratulations on your new job! So happy for you. • Long time no see! How have you been? • Shall we meet around 7? — Sounds good, see you then! | G13: オンラインで、祝い・近況・約束の確認まで含む社交的なやりとりをする。 | H13: 社会言語的適切さ＋テンポ：非同期のやりとりで型と応答を回す。 | I13: Long time no see! のような口語定型や、約束確認の Sounds good, see you then! のテンポある応答が出てこず、事務的な確認に終始しがち。日本語のオンライン社交の「クッション」を英語の口語定型に置き換える必要がある。 | J13: はがきの一方向から、オンラインの「往復する社交」へ。約束の設定・確認まで機能が広がる書面系列の到達点。
A15: DISCUSSION ── この行為をパターンとして読む（アレグザンダー式・行為全体への散文）
A16: 【この行為に「上級」は無い ── 儀礼型の本質】 苦情がA2からC1まで長い梯子を持つのに対し、挨拶・別れ・安否はPre-A1からA2+に完全に収まり、B1以上に記述文が一つも無い。これは欠落ではなく、交話的（phatic）行為の本質である。挨拶に高度な熟達は存在しない ── C2話者も "Hi, how are you?" と言う。CEFRがこの行為を初級だけで記述し尽くしているのは、関係の潤滑という機能が、初級の定型表現でほぼ充足されるからである。したがってこの行為のカタログは「レベルを上る」構造ではなく、「初級の型を、いかに場に合わせて選ぶか」という水平の広がりを持つ。 【難しさは「レベル」ではなく「レジスターとテンポ」にある】 では日本語話者にとって易しいかというと逆で、難所がレベル軸と直交する二つの次元に潜む。第一はレジスター（親しさ・改まりの選択）。sir/madam、Mr.＋姓、first name、ニックネームの使い分けは、日本語の「〜さん」一括感覚では捌けず、相手との距離を英語の呼称体系で測り直す必要がある。第二はテンポ。How are you? — Fine, thanks. And you? の往復は、中身ではなく「間髪入れず型を返す」ことに意味がある。この二つは文法でも語彙でもなく、how well の軸でいえば社会言語的適切さに全面的に属する。 【How are you? は質問ではない ── phatic の核心的誤解】 日本語話者が最もつまずくのは、儀礼的な問いを情報要求と受け取ることである。How are you? に実際の体調を長々答える、How's it going? に詰まる ── これは英語力ではなく、phatic communion（意味の交換ではなく接触の確認そのものが目的の発話）という概念が母語で意識されないために起こる。この行為を教えるとき、「中身より往復」「型は型として回す」という phatic の性質そのものを明示的に伝えることが、どの実例よりも効く。 【開始は言えるが、維持と終了が言えない】 日本語話者の挨拶は入口（Hello, Nice to meet you）に偏り、関係を「閉じる」定型（It was nice talking to you / Let's keep in touch / Have a nice day）の層が決定的に薄い。日本語では別れの挨拶がむしろ厚い（「それでは失礼します」「お世話になりました」）のに英語で出てこないのは、機能が同じでも表現が一対一で写らず、英語側の閉じる定型を別個の語彙として持っていないためである。カタログでは開始・維持・終了を必ず三点セットで示し、とりわけ終了の定型を厚くする。 【範型としての検証 ── 苦情型との対比で見えたこと】 苦情（指示型）では「緩衝の精緻化」がレベル軸を貫いたが、挨拶（儀礼型）ではレベル軸がほぼ消え、代わりに「レジスター選択」「テンポ」「phaticの理解」という水平の難しさが前面に出た。これは範型が行為の類型ごとに異なる顔を持つことを示す。指示型の点検軸（緩衝・二重の壁・隣接行為・口頭書面）はそのままでは効かず、儀礼型には「レベルの梯子が短い／無い」「難所がレジスターとテンポに移る」「phatic性の明示的説明が要る」という別の点検軸が要る。25行為を作り込む際は、まず各行為が指示型・儀礼型・主張型・表出型のどれに属するかを見極め、類型ごとの点検軸を当てるのが正しい ── 単一のテンプレートを全行為に機械適用してはならない。

Sheet 範型_事実質問応答
A1: 第1カタログ 範型 ── 発語内行為「事実情報の質問と応答（Asking & answering factual questions）」
A2: 類型：主張的（assertive）── 世界の事実を尋ね、真偽の判断を伴って答える ／ 本質：名前・時刻・場所・予定などの事実情報を、質問と応答のペアで往復させる。行為の核は情報の正確な授受であり、緩衝もレジスターも二次的。疑問文の構造そのものが遂行の要となる。
A4: モード | B4: レベル | C4: No. | D4: CEFR記述文（原文） | E4: 記述文（作業訳） | F4: 実例（exponent） | G4: 場面 | H4: 効くhow well軸 | I4: 日本語話者へのL1語用論注意 | J4: 隣接レベルとの差分
A5: 口頭 | B5: Pre-A1 | C5: 579 | D5: Can tell people their name and ask other people their names. | E5: 自分の名前を名乗り、他の人に名前を尋ねられる。 | F5: • What's your name? — My name is Kenji. / I'm Kenji. • And you? What's your name? | G5: 初対面で名前を尋ね合う、最も基本的な情報交換。 | H5: 文法的正確さ（疑問文の骨格）：What's your name? の語順を作れるか。 | I5: 日本語は「お名前は？」と述語を略しても成立するが、英語は What is your name? と疑問詞＋be動詞＋主語の語順が必須。主語を落として Name? だけだと幼稚か無礼に響く。疑問文の骨格そのものが最初の壁。 | J5: （起点）疑問文の最小形。事実の授受の最小単位。
A6: 口頭 | B6: Pre-A1 | C6: 585 | D6: Can ask very simple questions for information, such as “What is this?” and understand one- or two-word/sign answers. | E6: 「これは何?」等の簡単な情報の質問をし、1〜2語の答えを理解できる。 | F6: • What is this? — It's a key. • What's that in English? | G6: 物を指して名称を尋ね、短い答えを受け取る。 | H6: 文法的正確さ＋受容：What疑問文と一語応答の理解。 | I6: 答えの It's a key. の It's を省いて A key と答えるのは英語でも自然だが、日本語話者は逆に「これはキーです」に引きずられ This is key.（冠詞落ち）としがち。冠詞は日本語に無い範疇なので、事実応答のたびに落ちる。 | J6: 名前から一般の事物へ。What+be動詞の疑問を汎用化。
A7: 口頭 | B7: Pre-A1 | C7: 581 | D7: Can ask and tell what day, time of day and date it is. | E7: 何曜日か、一日のうちのいつか、何日かを尋ね、言える。 | F7: • What day is it today? — It's Monday. • What time is it? — It's half past three. • What's the date today? — It's the 5th of July. | G7: 曜日・時刻・日付という定型的事実を尋ね合う。 | H7: 文法的正確さ（非人称の it）：時刻・日付の it is 構文。 | I7: 時刻・曜日の主語 it（It's Monday）は日本語に対応物が無く、主語を落として Monday. とだけ答えがち。また half past three（3時半）like の英語独特の時刻表現は、日本語の「3時半」から直訳できず、型として覚える必要がある。 | J7: 事物から「定型的事実（時・日付）」へ。非人称itの構文が加わる。
A8: 口頭 | B8: A1 | C8: 575 | D8: Can ask and answer questions about themselves and other people, where they live, people they know, things they have. | E8: 自分や他の人、住んでいる場所、知っている人、持っているものについて質問し、答えられる。 | F8: • Where do you live? — I live in Osaka. • Do you have any brothers or sisters? — Yes, I have one sister. • Who's that? — That's my friend Aya. | G8: 居住地・家族・所有物など、身辺の事実を双方向に尋ね合う。 | H8: 文法的正確さ（一般動詞の疑問）：do/does を使った疑問文の構築。 | I8: Where do you live? の do は日本語に対応が無く、Where you live? と do を落とす誤りが頻発。日本語の疑問は語尾（〜か）だけで作れるため、英語の「助動詞doを前に立てる」操作が身につきにくい。主張型の中核的な文法的つまずき。 | J8: Pre-A1からの飛躍：be動詞疑問から一般動詞疑問（do支持）へ。扱う事実も身辺全般に拡大。
A9: 口頭 | B9: A2 | C9: 572 | D9: Can ask and answer simple questions about an event (e.g. ask where and when it took place, who was there and what it was like). | E9: 出来事について簡単な質問をし答えられる（どこで・いつ・誰が・どうだったか）。 | F9: • Where was the party? — It was at Kenji's place. • How was it? — It was really fun. • Who was there? — Aya and some people from work. | G9: 済んだ出来事について、場所・時・参加者・様子を尋ね合う。 | H9: 文法的正確さ（過去時制）：was/were と過去疑問の運用。 | I9: 過去の出来事なので was/were や did が要るが、日本語話者は時制標示を落として Where the party? / How it was?（語順崩れ）としやすい。日本語の過去「〜だった」は英語の時制ほど厳密な一致を求めないため、疑問文中の時制保持が弱い。 | J9: 現在の事実から「過去の出来事」へ。過去時制の疑問・応答が加わる。
A10: 口頭 | B10: A2 | C10: 570 | D10: Can ask for and give directions referring to a map or plan. | E10: 地図や見取り図を参照しながら道順を尋ね、教えられる。 | F10: • How do I get to the station? — Go straight and turn left at the bank. • Is it far? — No, about five minutes on foot. • Where are we now? — We're here, near the museum. | G10: 地図を見ながら、目的地への行き方を尋ね教え合う。 | H10: 叙述の正確さ＋文法（命令文の道案内）：方向表現の連鎖。 | I10: 道案内の応答は命令文（Go straight, Turn left）を使うが、日本語話者は命令形が強く聞こえると感じて避け、遠回しにしがち。英語では道案内の命令文は失礼でなく標準。また前置詞（at the bank, on your right）の選択が日本語の助詞感覚とずれる。 | J10: 口頭事実交換の応用：静的事実から「空間的手順の授受」へ。命令文応答が加わる。
A11: 口頭 | B11: A2+ | C11: 563 | D11: Can ask and answer questions about habits and routines. | E11: 習慣や日課について質問し、答えられる。 | F11: • What time do you usually get up? — Around seven. • How often do you exercise? — Twice a week. • Do you always take the train? — Usually, yes. | G11: 日常の習慣・頻度について尋ね合う。 | H11: 文法的正確さ（頻度・習慣の現在形）：頻度副詞と現在形の運用。 | I11: 頻度副詞（usually, often, twice a week）の位置が日本語と異なり、I usually get up... の語中位置を外して文末や文頭に置きがち。また習慣を表す現在形と進行形の別（I take the train / I'm taking）が、日本語の「〜している」一括感覚で混同される。 | J11: 単発の出来事から「反復する習慣」へ。頻度表現と習慣の現在形が加わる。
A12: 口頭 | B12: A2+ | C12: 565 | D12: Can ask and answer questions about plans and intentions. | E12: 計画や意図について質問し、答えられる。 | F12: • What are you doing this weekend? — I'm meeting some friends. • Are you going to travel this summer? — Yes, I'm planning to. • What time will you arrive? — Probably around six. | G12: 予定・意図について尋ね合う。 | H12: 文法的正確さ（未来表現の選択）：will / be going to / 現在進行形の使い分け。 | I12: 英語の未来表現は三系統（will＝その場の決定・予測、be going to＝既定の意図、現在進行形＝手配済みの予定）あるが、日本語の「〜する／〜するつもり」の二分では捌けず、どれを使うか判断できない。この使い分けは主張型・未来事実の最大の難所。 | J12: 過去・現在の事実から「未来の予定・意図」へ。未来表現の体系が加わる。主張型口頭系列の到達点。
A13: 書面 | B13: A1 | C13: 643 | D13: Can convey personal information of a routine nature, for example in a short e-mail or letter introducing themselves. | E13: 日常的な個人情報を伝えられる（自己紹介する短いメールなど）。 | F13: • Hi, I'm Kenji. I'm from Osaka and I work at a software company. • I have two cats and I like hiking. What about you? | G13: 自己紹介のメールで、身辺の事実情報を文章で伝える。 | H13: 文法的正確さ（平叙文の事実記述）：I am / I have / I work の平叙連鎖。 | I13: 口頭では往復で成立するが、書面では自己完結した平叙文を連ねる必要がある。日本語話者は主語 I の反復を冗長に感じて落としがちだが、英語では各文に主語が要る。話し言葉の省略を書면に持ち込むと非文になる。 | J13: （書面起点）口頭の質問応答が、書面では一方向の事実記述として立ち上がる。
A14: 書面 | B14: A2 | C14: 642 | D14: Can exchange information by text message, by e-mail or in short letters, responding to questions from the other person (e.g. about a new product or activity). | E14: テキスト・メール・短い手紙で情報を交換できる（相手の質問に答えながら）。 | F14: • Q: When does the event start? — A: It starts at 2 pm on Saturday. • Q: Where is it? — A: At the community hall, near the station. | G14: メールやテキストで、相手の質問に答えつつ事実情報をやりとりする。 | H14: 文法的正確さ＋叙述の正確さ：問いに対応した事実の返信。 | I14: 書面の非同期往復では、相手の質問の時制・焦点に合わせて答える必要があるが、日本語話者は質問を受け止めず自分の言いたい情報を返しがち（質問と応答のかみ合わせのずれ）。英語のQ&Aは問いの構造に応答を対応させる明示性が要る。 | J14: 自己紹介の一方向から、書面の「往復する情報交換」へ。書面系列の到達点。
A16: DISCUSSION ── この行為をパターンとして読む（アレグザンダー式・行為全体への散文）
A17: 【主張型の核は疑問文の構造そのものである】 苦情（指示型）の核が緩衝、挨拶（儀礼型）の核がレジスターとテンポだったのに対し、事実情報の質問と応答（主張型）の核は、疑問文と応答の文法構造そのものにある。この行為で一貫して効く how well 軸は社会言語的適切さではなく文法的正確さである。What's your name? / Where do you live? / What are you doing this weekend? ── レベルが上がるとは、扱える疑問の時制と法が広がること（be動詞疑問→do支持疑問→過去疑問→未来表現の三系統）にほかならない。緩衝もレジスターも、この行為ではほぼ問われない。 【日本語話者のつまずきは「疑問文の作り方」に集中する】 指示型・儀礼型のL1問題が語用論（言い出せない、phaticの誤解）だったのに対し、主張型のL1問題は純粋に文法・統語に寄る。第一に do 支持 ── 日本語は語尾「〜か」だけで疑問を作れるため、Where do you live? の do を立てる操作が身につかず Where you live? が頻発する。第二に時制の保持 ── 疑問文中で was/did を落とす。第三に冠詞と主語 ── This is key. / 主語Iの脱落。これらは語用論的配慮ではなく、日本語に存在しない文法範疇（助動詞do、厳密な時制一致、冠詞）が事実の授受のたびに露出する現象である。したがってこの行為のL1注意は「文化」ではなく「構造」を突くものになる。 【未来表現の三系統が唯一の高度な難所】 主張型はおおむね平明だが、一点だけ質的な難所がある ── 未来の予定・意図（A2+）を表す will / be going to / 現在進行形の使い分けである。日本語の「〜する／〜するつもり」の二分では英語の三系統に対応できない。ここだけは文法項目の暗記では足りず、話者の心的態度（その場の決定か、既定の意図か、手配済みか）と結びつけて教える必要がある。カタログではこの一点を厚く扱う。 【口頭は往復、書面は自己完結】 情報交換はCEFRでは圧倒的に口頭（Information exchange スケール）に記述が集中し、書面はCorrespondence由来の情報記述が少数あるのみ。この非対称は本質的で、事実の授受は本来リアルタイムの往復（Q — A）に最も自然に宿る。書面に移ると、口頭の省略（主語や述語の脱落）が使えず、自己完結した平叙文を連ねる必要が生じる ── 話し言葉の省略を書面に持ち込むと非文になる、という書面固有の壁が現れる。 【範型としての検証 ── 主張型の点検軸】 主張型に効く点検軸は、指示型・儀礼型と異なる。(1) レベル軸は「疑問の時制・法の拡大」として明快に立つ（初級で出尽くすが、内部に文法的段階がある）。(2) L1注意は語用論ではなく統語（do支持・時制・冠詞・主語）を突く。(3) how well の主軸は文法的正確さ。(4) 唯一の高度な難所は未来表現の三系統。(5) 口頭往復と書面自己完結の差。この5点が、同じ主張型の他行為（自己に関する情報提供、経験・出来事の叙述、問題・事情の説明など）を作る際の点検リストになる。ただし主張型内でも「経験・出来事の叙述」は疑問応答ではなく一方向の語りなので、疑問文構造の軸が効かない可能性がある ── これは汎用性検証で確かめるべき論点である。

Sheet 範型_意見表明
A1: 第1カタログ 範型 ── 発語内行為「意見・見解の表明（Expressing opinions & views）」
A2: 類型：表出的（expressive）＋主張的要素 ── 話者の心的態度（賛否・評価）を表明し、根拠で支える ／ 本質：ある事柄について自分の立場・評価・信念を述べ、レベルが上がるほど根拠と論拠で支え、他者の見解と関係づける。主張の中身より、立場表明の型と、対立を許容する作法が要となる。
A4: モード | B4: レベル | C4: No. | D4: CEFR記述文（原文） | E4: 記述文（作業訳） | F4: 実例（exponent） | G4: 場面 | H4: 効くhow well軸 | I4: 日本語話者へのL1語用論注意 | J4: 隣接レベルとの差分
A5: 口頭 | B5: A2 | C5: 479 | D5: Can express opinions in a limited way. | E5: 意見を限られた形で表明できる。 | F5: • I think it's good. • I like it. / I don't like it. • For me, it's too expensive. | G5: 身近な事柄に、ごく短く賛否や評価を述べる。 | H5: 文法（I think 節）：I think + 文 の骨格。 | I5: I think を付けずに It's good. と言い切ると断定に響く。日本語は「〜と思う」を多用して主観を和らげるが、英語でも I think は立場表明の基本枠。ただし日本語の「思う」ほど義務的ではなく、乱発すると自信なさげにも響く、という温度差がある。 | J5: （起点）意見表明の最小形。I think＋評価語のみ。
A6: 口頭 | B6: A2+ | C6: 473 | D6: Can exchange opinions and compare things and people using simple language. | E6: 簡単な言葉で意見を交換し、物や人を比較できる。 | F6: • I think summer is better than winter. • This one is nicer, but that one is cheaper. • What do you think? — I agree. / I'm not sure. | G6: 二つの選択肢を比べ、意見を交換し合う。 | H6: 文法（比較級）＋社会言語的適切さ：比較構文と同意/留保の応答。 | I6: 比較級（better than, nicer）の構造は日本語の「〜より」と語順が逆で作りにくい。また I'm not sure.（やんわり不同意）のような中間的応答の層が薄く、賛成か沈黙かの二択になりがち。 | J6: 単独の意見から「意見の交換と比較」へ。比較と応答の往復が加わる。
A7: 口頭 | B7: B1 | C7: 471 | D7: Can express beliefs, opinions and agreement and disagreement politely. | E7: 信念・意見・賛否を丁寧に表明できる。 | F7: • I see your point, but I think... • I agree with you up to a point. • Actually, I don't really think that's true. | G7: 議論の中で、賛成・反対を相手を立てつつ丁寧に表明する。 | H7: 社会言語的適切さ（不同意の緩衝）：反対を丁寧に包めるか。 | I7: ここが表出型最大のL1難所。日本語話者は不同意を避けて曖昧にするか、逆に But that's wrong. と裸で否定して角を立てるかに振れる。英語は I see your point, but... / I'm not sure I agree で、相手をまず受けてから反対する型が定石。この「受けてから返す」二段構えは明示的に教える必要がある。 | J7: A2+からの飛躍：単なる評価から「賛否の丁寧な表明」へ。不同意の緩衝が中心課題に。
A8: 口頭 | B8: B1+ | C8: 464 | D8: Can express their thoughts about abstract or cultural topics such as music or films. | E8: 音楽や映画などの抽象的・文化的な話題について考えを表現できる。 | F8: • What I like about this film is how it handles memory. • It's not really my kind of music, but I can see why people love it. • The story felt a bit slow, but the ending made up for it. | G8: 映画・音楽など抽象度の高い対象に、込み入った感想を述べる。 | H8: 叙述の正確さ＋語彙範囲：抽象的評価の語彙と構造。 | I8: 抽象的対象の評価は、日本語では「よかった／いまいち」で済ませがちだが、英語では what I like about X is... のような焦点化構文や、譲歩（but I can see why...）を使って立場を立体的に述べる。この構文の層を持たないと、抽象評価が幼く聞こえる。 | J8: 身近な物から「抽象的・文化的対象」へ。評価語彙と焦点化構文が加わる。
A9: 口頭 | B9: B2 | C9: 462 | D9: Can account for and sustain their opinions in discussion by providing relevant explanations, arguments and comments. | E9: 適切な説明・論拠・コメントを提供して、議論の中で自分の意見を述べ、支持できる。 | F9: • I'd argue that... for two reasons. First,... Second,... • That's a fair point, but the evidence actually suggests otherwise. • I stand by what I said, because... | G9: 議論で自分の立場を、根拠を挙げて主張し、反論にも耐えて維持する。 | H9: 話題の展開＋叙述の正確さ：意見を論拠で構造的に支える。 | I9: 「意見を論拠で支え、維持する」は日本語話者に不慣れ。日本語の議論は結論を曖昧に残す作法もあるが、英語では I'd argue that... because... と立場と根拠を明示し、反論されても I stand by... と保持することが誠実とされる。撤回しすぎると立場が無いと見なされる。 | J9: B1+からの飛躍：感想の表明から「論拠で支え維持する主張」へ。表出が論証に接続する。
A10: 口頭 | B10: C1 | C10: 670 | D10: Can evaluate, restate and challenge arguments in professional or academic live online chat and discussion. | E10: 専門的・学術的なライブのオンライン議論で、論を評価・言い直し・反論できる。 | F10: • If I understand your position correctly, you're saying... — but that assumes... • I'd push back on that slightly. The data you cite doesn't quite support... • Let me reframe: the real question isn't X, it's Y. | G10: 専門的議論で、相手の論を正確に捉え直し、的確に反論・再構成する。 | H10: 叙述の正確さ＋柔軟さ（最大）：論の評価・言い直し・反論の精密制御。 | I10: C1では相手の論を restate（言い直して確認）してから challenge する高度な型が要る。日本語話者は相手の論の要約確認を飛ばして直接反論しがちで、議論がかみ合わない。If I understand you correctly...→but... の型は、正確さと礼節を両立させる英語アカデミック議論の作法として明示的に習得を要する。 | J10: B2からの到達点：主張の維持から「他者の論の評価・再構成・反論」へ。表出型口頭系列の頂点。
A11: 書面 | B11: A2 | C11: 683 | D11: Can make brief positive or negative comments online about embedded links and media using a repertoire of basic language, though they will generally have to refer to an online translation tool and other resources. | E11: 埋め込みリンクやメディアに、基本的な言葉で短い肯定・否定コメントをオンラインでできる。 | F11: • Love this! 😍 • Not for me, sorry. • So true! | G11: SNSの投稿やリンクに、短い賛否のコメントを付ける。 | H11: 社会言語的適切さ（オンライン簡略表現）：口語的な短評の型。 | I11: 英語オンラインの超短評（So true! / Not for me / This!）の語彙が乏しく、硬い I think this is good. で返しがち。日本語の「わかる」「それな」に当たる口語共感表現を、英語の型として別途持つ必要がある。 | J11: （書面起点）口頭の意見表明が、オンラインでは超短評として立ち上がる。
A12: 書面 | B12: B1 | C12: 677 | D12: Can post a comprehensible contribution in an online discussion on a familiar topic of interest, provided they can prepare the text beforehand and use online tools to fill gaps in language and check accuracy. | E12: 事前に準備できれば、関心のある身近な話題のオンライン議論に理解可能な投稿ができる。 | F12: • I think the article raises a good point about remote work, but it overlooks the cost side. • In my experience, this approach works better for small teams. | G12: 準備の上で、オンライン議論に理由を添えた意見を投稿する。 | H12: 叙述の正確さ（書面）：準備された、自己完結した意見投稿。 | I12: 書面の意見投稿では、口頭の往復に頼れず、立場＋理由を一つの投稿で自己完結させる必要がある。日本語話者は結論を最後に置き前置きを長くしがちだが、英語オンライン議論は要点先行（I think X, but Y）が読まれやすい。 | J12: 超短評から「理由を添えた議論への投稿」へ。準備を挟んだ自己完結した表明。
A13: 書面 | B13: B1+ | C13: 635 | D13: Can compose personal letters giving news and expressing thoughts about abstract or cultural topics such as music or film. | E13: 近況を伝え、音楽や映画などの抽象的・文化的話題についての考えを表現する個人的な手紙を書ける。 | F13: • I finally watched that film you recommended. I loved the visuals, though the plot lost me a bit. • Lately I've been getting into jazz — there's something about it that really calms me down. | G13: 私信で、近況とともに文化的対象への考えを綴る。 | H13: 叙述の正確さ＋語彙範囲：私信レジスターでの抽象的感想。 | I13: 私信での考えの表明は、口語的親密さと一定の内容を両立させる。日本語の手紙の様式（時候の挨拶等）を英語に持ち込むと不自然で、英語私信は近況と感想を地続きに書く。この様式差は書面ならではの注意点。 | J13: 議論投稿から「私信での考えの表明」へ。親密なレジスターでの抽象的感想。書面系列の到達点。
A15: DISCUSSION ── この行為をパターンとして読む（アレグザンダー式・行為全体への散文）
A16: 【表出型の核は「不同意を許容する作法」である】 苦情（指示型）の核が緩衝、挨拶（儀礼型）がレジスターとテンポ、事実Q&A（主張型）が疑問文構造だったのに対し、意見・見解の表明（表出型）の核は、立場の表明と、とりわけ対立を許容し丁寧に扱う作法にある。レベルが上がるとは、意見を「述べる」だけから、根拠で「支え」、他者の論と「関係づけ」、最終的に「評価・再構成・反論する」へと、社会的な議論の営みへ深化することである。効く how well 軸は、低位では文法（I think節・比較級）だが、B1以降は社会言語的適切さと叙述の正確さ（論拠の構造）へ移る。 【最大のL1難所は「受けてから返す」不同意の型】 日本語話者にとって表出型の中心的困難は、不同意の扱いにある。日本語文化では公然の不同意が回避されやすく、その結果、英語でも二つの失敗形に振れる ── 曖昧にして立場を消すか、But that's wrong. と裸で否定して角を立てるか。英語の作法は第三の道で、I see your point, but... / That's a fair point, but... と、まず相手を受けてから反対する二段構えである。この「受けてから返す」型は、B1で登場しC1まで一貫して深化する（C1では相手の論を restate してから challenge する）。表出型カタログの背骨は、この不同意の作法の段階的精緻化として引くべきである。 【意見は「維持」まで含めて一つの行為である】 主張型の事実Q&Aが単発の授受で完結するのに対し、意見表明はB2で「維持する（sustain）」が加わる点が質的に異なる。I stand by what I said, because... ── 反論されても根拠とともに立場を保つことが、英語では誠実さとされる。日本語話者は対立を避けて安易に撤回しがちだが、それは英語の議論では「立場が無い」と受け取られる。表明・支持・維持を一続きの行為として示すことが、この行為のカタログの要点である。 【抽象的対象には専用の構文がある】 B1+以降、評価対象が身近な物から抽象的・文化的対象（音楽・映画・思想）へ移ると、what I like about X is... の焦点化構文や、I can see why..., though... の譲歩構文が要る。日本語の「よかった／いまいち」の二元では抽象評価が幼く響く。この構文層は語彙ではなく「立場を立体的に述べる型」であり、表出型に固有の習得課題である。 【範型としての検証 ── 表出型の点検軸】 表出型に効く点検軸：(1) レベル軸は「表明→支持→維持→評価・反論」という議論の深化として長く立つ（苦情型に似て梯子が長い）。(2) L1注意の中心は不同意の作法（受けてから返す）。(3) how well の主軸は低位で文法、B1以降は社会言語的適切さ＋叙述の正確さへ移動する。(4) 意見の「維持」が行為の一部。(5) 抽象的対象用の焦点化・譲歩構文。この5点が、同じ表出型の他行為（感情の表出、好悪の表明、感謝・詫び・祝意など）を作る際の点検リストになる。ただし表出型内でも「感謝・詫び」は定型性が高く儀礼型に近い顔を持つ可能性があり、「感情の表出」は不同意の作法が効かない ── 表出型は内部の振れ幅が大きく、汎用性検証で下位分化を確かめる必要がある。

Sheet 類型別点検軸
A1: 四類型の点検軸 ── 範型から抽出した、類型別テンプレートの骨子
A2: 類型 | B2: 範型とした行為 | C2: レベル軸の性格 | D2: L1注意の中心 | E2: 効くhow well主軸 | F2: 汎用性検証で確かめる論点
A3: 指示型 (directive) | B3: 苦情・クレーム | C3: A2→C1の長い梯子。緩衝の精緻化として一直線に読める | D3: 言い出せない／振れすぎるの二重の壁。緩衝技法の欠如 | E3: 社会言語的適切さ（緩衝） | F3: 依頼・要求に当てて、緩衝軸と口頭書面分岐がそのまま効くか
A4: 儀礼型 (phatic) | B4: 挨拶・別れ・安否 | C4: Pre-A1〜A2+で出尽くす。上級が無い。レベル軸がほぼ消える | D4: phaticの誤解（How are you?を情報要求と取る）。レジスターとテンポ。終了定型の欠如 | E4: 社会言語的適切さ（レジスター） | F4: 会話の開始・維持に当てて、レベル軸消失とphatic説明が効くか
A5: 主張型 (assertive) | B5: 事実情報の質問と応答 | C5: 初中級で出尽くすが、内部に疑問の時制・法の文法的段階 | D5: 語用論でなく統語（do支持・時制・冠詞・主語の脱落） | E5: 文法的正確さ | F5: 経験・出来事の叙述に当てて、疑問文構造の軸が効くか（一方向の語りでは効かない可能性）
A6: 表出型 (expressive) | B6: 意見・見解の表明 | C6: A2→C1の長い梯子。表明→支持→維持→評価・反論と深化 | D6: 不同意の作法（受けてから返す）。安易な撤回／裸の否定 | E6: 社会言語的適切さ＋叙述の正確さ | F6: 感謝・詫び（定型的で儀礼型寄り）／感情の表出（不同意作法が効かない）で下位分化を確認
A8: 四類型すべてに範型を1つずつ作成完了。次段階：各類型内で範型を「同類の別行為」に適用し、テンプレートの汎用性を検証する（右端列の論点）。単一テンプレートの全行為機械適用は不可 ── 類型判定→類型別テンプレート→類型内検証の三段が量産の前提。

Sheet 発語内行為インベントリ
A1: 大類型 | B1: 発語内行為 | C1: 記述文数 | D1: Pre-A1 | E1: A1 | F1: A2 | G1: B1 | H1: B2 | I1: C1 | J1: C2 | K1: 最低レベル | L1: 該当No.
A2: 交話・儀礼 | B2: 挨拶・別れ・安否 | C2: 9 | D2: 3 | E2: 3 | F2: 3 | K2: Pre-A1 | L2: 438, 444, 451, 452, 453, 455, 648, 682, 686
A3: 交話・儀礼 | B3: 会話の開始・維持 | C3: 5 | E3: 1 | F3: 1 | G3: 2 | H3: 1 | K3: A1 | L3: 427, 432, 434, 445, 450
A4: 表出 | B4: 意見・見解の表明 | C4: 18 | F4: 4 | G4: 10 | H4: 3 | I4: 1 | K4: A2 | L4: 460, 462, 464, 466, 469, 470, 471, 473, 479, 512, 514, 515, 635, 670, 672, 677, 681, 683
A5: 表出 | B5: 感情の表出 | C5: 8 | F5: 1 | G5: 5 | H5: 2 | K5: A2 | L5: 431, 437, 447, 630, 636, 639, 676, 678
A6: 表出 | B6: 感謝・詫び・祝意 | C6: 6 | E6: 1 | F6: 4 | H6: 1 | K6: A1 | L6: 441, 446, 632, 644, 646, 685
A7: 表出 | B7: 好悪の表明 | C7: 4 | E7: 3 | F7: 1 | K7: A1 | L7: 448, 480, 647, 684
A8: 表出 | B8: 理解状態の表明 | C8: 3 | E8: 2 | F8: 1 | K8: A1 | L8: 745, 747, 748
A9: 主張 | B9: 事実情報の授受 | C9: 15 | E9: 1 | F9: 6 | G9: 6 | H9: 2 | K9: A1 | L9: 541, 554, 555, 557, 559, 562, 568, 591, 633, 640, 642, 649, 656, 659, 679
A10: 主張 | B10: 事実情報の質問と応答 | C10: 15 | D10: 6 | E10: 3 | F10: 6 | K10: Pre-A1 | L10: 563, 564, 565, 569, 570, 572, 574, 575, 578, 579, 581, 582, 583, 584, 585
A11: 主張 | B11: 問題・事情の説明 | C11: 8 | E11: 1 | F11: 2 | G11: 4 | H11: 1 | K11: A1 | L11: 465, 511, 529, 590, 593, 596, 598, 600
A12: 主張 | B12: 面接での質問と応答 | C12: 6 | F12: 2 | G12: 2 | H12: 2 | K12: A2 | L12: 588, 589, 592, 594, 595, 597
A13: 主張 | B13: 伝言の授受 | C13: 6 | E13: 1 | F13: 1 | G13: 3 | H13: 1 | K13: A1 | L13: 653, 654, 655, 657, 658, 662
A14: 主張 | B14: 自己に関する情報提供 | C14: 5 | D14: 2 | E14: 1 | F14: 2 | K14: Pre-A1 | L14: 571, 599, 643, 650, 687
A15: 主張 | B15: 経験・出来事の叙述 | C15: 1 | F15: 1 | K15: A2+ | L15: 680
A16: 指示 | B16: 明確化・繰り返しの要求 | C16: 14 | F16: 4 | G16: 5 | H16: 3 | I16: 2 | K16: A2 | L16: 531, 668, 699, 702, 704, 737, 738, 739, 740, 741, 742, 743, 744, 746
A17: 指示 | B17: 取引（購入・注文） | C17: 12 | D17: 1 | F17: 8 | G17: 1 | H17: 1 | I17: 1 | K17: Pre-A1 | L17: 537, 539, 540, 542, 543, 545, 549, 691, 695, 700, 703, 705
A18: 指示 | B18: 苦情・クレーム | C18: 9 | F18: 1 | G18: 3 | H18: 4 | I18: 1 | K18: A2 | L18: 526, 527, 532, 533, 544, 625, 628, 629, 638
A19: 指示 | B19: 提案・誘い・計画の相談 | C19: 8 | F19: 5 | G19: 1 | H19: 2 | K19: A2 | L19: 467, 474, 475, 477, 478, 508, 645, 697
A20: 指示 | B20: 依頼・要求 | C20: 6 | E20: 3 | F20: 3 | K20: A1 | L20: 442, 519, 522, 538, 546, 547
A21: 指示 | B21: 問い合わせ | C21: 3 | F21: 1 | G21: 1 | H21: 1 | K21: A2 | L21: 528, 637, 706
A22: 指示 | B22: 道案内の依頼と提供 | C22: 3 | F22: 2 | G22: 1 | K22: A2+ | L22: 517, 558, 566
A23: 指示 | B23: 助言 | C23: 2 | G23: 1 | J23: 1 | K23: B1 | L23: 456, 560
A24: 指示 | B24: 同意・不同意 | C24: 2 | F24: 1 | H24: 1 | K24: A2+ | L24: 428, 476
A25: 指示 | B25: 応募・出願 | C25: 1 | G25: 1 | K25: B1 | L25: 641
A26: 指示 | B26: 指示への応答 | C26: 1 | F26: 1 | K26: A2 | L26: 707
A28: 言語行為論的に純粋なcan do＝170記述文を発語内行為で集約すると25種。サール類型: 交話・儀礼/表出/主張/指示。列はレベル別記述文数（プラスレベルは基本級に集約）。上級ほど新規行為は増えず、既存行為のhow well化が進む。

Sheet サマリー
A1: CEFR Companion Volume 2020 記述文（Descriptor）全数集計
A2: 出典: CEFR_Descriptors__2020_.xlsx（Englishシート）。訳語の正準は「対訳マスタ」シート（作業訳・公式訳併記）。プレースホルダ行はReal=0として集計から除外。
A4: データ行（空行除く） | B4: =COUNTA(Data!$A$2:$A$1833) -> 1832
A5: 実記述文（プレースホルダ除外） | B5: =SUM(Data!$H$2:$H$1833) -> 1712
A6: うち 手話能力（対象外） | B6: =COUNTIFS(Data!$B$2:$B$1833,"Signing competences",Data!$H$2:$H$1833,1) -> 488
A7: 音声言語の実記述文 | B7: =B5-B6 -> 1224
A9: スキーム × レベル（実記述文）
A10: スキーム | B10: Pre-A1 | C10: A1 | D10: A2 | E10: A2+ | F10: B1 | G10: B1+ | H10: B2 | I10: B2+ | J10: C1 | K10: C2 | L10: 計 | N10: EN:Scheme
A11: =IFERROR(INDEX(対訳マスタ!$C$2:$C$136,MATCH($N11,対訳マスタ!$B$2:$B$136,0)),$N11) -> コミュニケーション言語活動 | B11: =COUNTIFS(Data!$B$2:$B$1833,$N11,Data!$F$2:$F$1833,B$10,Data!$H$2:$H$1833,1) -> 41 | C11: =COUNTIFS(Data!$B$2:$B$1833,$N11,Data!$F$2:$F$1833,C$10,Data!$H$2:$H$1833,1) -> 78 | D11: =COUNTIFS(Data!$B$2:$B$1833,$N11,Data!$F$2:$F$1833,D$10,Data!$H$2:$H$1833,1) -> 115 | E11: =COUNTIFS(Data!$B$2:$B$1833,$N11,Data!$F$2:$F$1833,E$10,Data!$H$2:$H$1833,1) -> 85 | F11: =COUNTIFS(Data!$B$2:$B$1833,$N11,Data!$F$2:$F$1833,F$10,Data!$H$2:$H$1833,1) -> 131 | G11: =COUNTIFS(Data!$B$2:$B$1833,$N11,Data!$F$2:$F$1833,G$10,Data!$H$2:$H$1833,1) -> 80 | H11: =COUNTIFS(Data!$B$2:$B$1833,$N11,Data!$F$2:$F$1833,H$10,Data!$H$2:$H$1833,1) -> 115 | I11: =COUNTIFS(Data!$B$2:$B$1833,$N11,Data!$F$2:$F$1833,I$10,Data!$H$2:$H$1833,1) -> 68 | ... K11: =COUNTIFS(Data!$B$2:$B$1833,$N11,Data!$F$2:$F$1833,K$10,Data!$H$2:$H$1833,1) -> 60 | L11: =SUM(B11:K11) -> 874 | N11: Communicative language activities
A12: =IFERROR(INDEX(対訳マスタ!$C$2:$C$136,MATCH($N12,対訳マスタ!$B$2:$B$136,0)),$N12) -> コミュニケーション言語方略 | B12: =COUNTIFS(Data!$B$2:$B$1833,$N12,Data!$F$2:$F$1833,B$10,Data!$H$2:$H$1833,1) -> 2 | C12: =COUNTIFS(Data!$B$2:$B$1833,$N12,Data!$F$2:$F$1833,C$10,Data!$H$2:$H$1833,1) -> 5 | D12: =COUNTIFS(Data!$B$2:$B$1833,$N12,Data!$F$2:$F$1833,D$10,Data!$H$2:$H$1833,1) -> 11 | E12: =COUNTIFS(Data!$B$2:$B$1833,$N12,Data!$F$2:$F$1833,E$10,Data!$H$2:$H$1833,1) -> 7 | F12: =COUNTIFS(Data!$B$2:$B$1833,$N12,Data!$F$2:$F$1833,F$10,Data!$H$2:$H$1833,1) -> 18 | G12: =COUNTIFS(Data!$B$2:$B$1833,$N12,Data!$F$2:$F$1833,G$10,Data!$H$2:$H$1833,1) -> 16 | H12: =COUNTIFS(Data!$B$2:$B$1833,$N12,Data!$F$2:$F$1833,H$10,Data!$H$2:$H$1833,1) -> 21 | I12: =COUNTIFS(Data!$B$2:$B$1833,$N12,Data!$F$2:$F$1833,I$10,Data!$H$2:$H$1833,1) -> 12 | ... K12: =COUNTIFS(Data!$B$2:$B$1833,$N12,Data!$F$2:$F$1833,K$10,Data!$H$2:$H$1833,1) -> 8 | L12: =SUM(B12:K12) -> 116 | N12: Communicative language strategies
A13: =IFERROR(INDEX(対訳マスタ!$C$2:$C$136,MATCH($N13,対訳マスタ!$B$2:$B$136,0)),$N13) -> コミュニケーション言語能力 | B13: =COUNTIFS(Data!$B$2:$B$1833,$N13,Data!$F$2:$F$1833,B$10,Data!$H$2:$H$1833,1) -> 4 | C13: =COUNTIFS(Data!$B$2:$B$1833,$N13,Data!$F$2:$F$1833,C$10,Data!$H$2:$H$1833,1) -> 15 | D13: =COUNTIFS(Data!$B$2:$B$1833,$N13,Data!$F$2:$F$1833,D$10,Data!$H$2:$H$1833,1) -> 22 | E13: =COUNTIFS(Data!$B$2:$B$1833,$N13,Data!$F$2:$F$1833,E$10,Data!$H$2:$H$1833,1) -> 10 | F13: =COUNTIFS(Data!$B$2:$B$1833,$N13,Data!$F$2:$F$1833,F$10,Data!$H$2:$H$1833,1) -> 25 | G13: =COUNTIFS(Data!$B$2:$B$1833,$N13,Data!$F$2:$F$1833,G$10,Data!$H$2:$H$1833,1) -> 8 | H13: =COUNTIFS(Data!$B$2:$B$1833,$N13,Data!$F$2:$F$1833,H$10,Data!$H$2:$H$1833,1) -> 36 | I13: =COUNTIFS(Data!$B$2:$B$1833,$N13,Data!$F$2:$F$1833,I$10,Data!$H$2:$H$1833,1) -> 11 | ... K13: =COUNTIFS(Data!$B$2:$B$1833,$N13,Data!$F$2:$F$1833,K$10,Data!$H$2:$H$1833,1) -> 18 | L13: =SUM(B13:K13) -> 182 | N13: Communicative language competences
A14: =IFERROR(INDEX(対訳マスタ!$C$2:$C$136,MATCH($N14,対訳マスタ!$B$2:$B$136,0)),$N14) -> 複言語・複文化能力 | B14: =COUNTIFS(Data!$B$2:$B$1833,$N14,Data!$F$2:$F$1833,B$10,Data!$H$2:$H$1833,1) -> 0 | C14: =COUNTIFS(Data!$B$2:$B$1833,$N14,Data!$F$2:$F$1833,C$10,Data!$H$2:$H$1833,1) -> 3 | D14: =COUNTIFS(Data!$B$2:$B$1833,$N14,Data!$F$2:$F$1833,D$10,Data!$H$2:$H$1833,1) -> 10 | E14: =COUNTIFS(Data!$B$2:$B$1833,$N14,Data!$F$2:$F$1833,E$10,Data!$H$2:$H$1833,1) -> 0 | F14: =COUNTIFS(Data!$B$2:$B$1833,$N14,Data!$F$2:$F$1833,F$10,Data!$H$2:$H$1833,1) -> 13 | G14: =COUNTIFS(Data!$B$2:$B$1833,$N14,Data!$F$2:$F$1833,G$10,Data!$H$2:$H$1833,1) -> 0 | H14: =COUNTIFS(Data!$B$2:$B$1833,$N14,Data!$F$2:$F$1833,H$10,Data!$H$2:$H$1833,1) -> 15 | I14: =COUNTIFS(Data!$B$2:$B$1833,$N14,Data!$F$2:$F$1833,I$10,Data!$H$2:$H$1833,1) -> 0 | ... K14: =COUNTIFS(Data!$B$2:$B$1833,$N14,Data!$F$2:$F$1833,K$10,Data!$H$2:$H$1833,1) -> 3 | L14: =SUM(B14:K14) -> 52 | N14: Plurilingual and pluricultural competence
A15: =IFERROR(INDEX(対訳マスタ!$C$2:$C$136,MATCH($N15,対訳マスタ!$B$2:$B$136,0)),$N15) -> 手話能力 | B15: =COUNTIFS(Data!$B$2:$B$1833,$N15,Data!$F$2:$F$1833,B$10,Data!$H$2:$H$1833,1) -> 0 | C15: =COUNTIFS(Data!$B$2:$B$1833,$N15,Data!$F$2:$F$1833,C$10,Data!$H$2:$H$1833,1) -> 47 | D15: =COUNTIFS(Data!$B$2:$B$1833,$N15,Data!$F$2:$F$1833,D$10,Data!$H$2:$H$1833,1) -> 46 | E15: =COUNTIFS(Data!$B$2:$B$1833,$N15,Data!$F$2:$F$1833,E$10,Data!$H$2:$H$1833,1) -> 41 | F15: =COUNTIFS(Data!$B$2:$B$1833,$N15,Data!$F$2:$F$1833,F$10,Data!$H$2:$H$1833,1) -> 65 | G15: =COUNTIFS(Data!$B$2:$B$1833,$N15,Data!$F$2:$F$1833,G$10,Data!$H$2:$H$1833,1) -> 61 | H15: =COUNTIFS(Data!$B$2:$B$1833,$N15,Data!$F$2:$F$1833,H$10,Data!$H$2:$H$1833,1) -> 67 | I15: =COUNTIFS(Data!$B$2:$B$1833,$N15,Data!$F$2:$F$1833,I$10,Data!$H$2:$H$1833,1) -> 58 | ... K15: =COUNTIFS(Data!$B$2:$B$1833,$N15,Data!$F$2:$F$1833,K$10,Data!$H$2:$H$1833,1) -> 35 | L15: =SUM(B15:K15) -> 488 | N15: Signing competences
A16: 計 | B16: =SUM(B11:B15) -> 47 | C16: =SUM(C11:C15) -> 148 | D16: =SUM(D11:D15) -> 204 | E16: =SUM(E11:E15) -> 143 | F16: =SUM(F11:F15) -> 252 | G16: =SUM(G11:G15) -> 165 | H16: =SUM(H11:H15) -> 254 | I16: =SUM(I11:I15) -> 149 | ... L16: =SUM(L11:L15) -> 1712

Sheet Data
A1: No | B1: Scheme | C1: Mode | D1: Activity | E1: Scale | F1: Level | G1: Descriptor | H1: Real
A2: 1 | B2: Communicative language activities | C2: Reception | D2: Oral comprehension | E2: Overall oral comprehension | F2: C2 | G2: Can understand with ease virtually any kind of language, whether live or broadcast, delivered at fast natural speed. | H2: 1
A3: 2 | B3: Communicative language activities | C3: Reception | D3: Oral comprehension | E3: Overall oral comprehension | F3: C1 | G3: Can understand enough to follow extended discourse on abstract and complex topics beyond their own field, though they may need to confirm occasional details, especially if the variety is unfamiliar. | H3: 1
A4: 3 | B4: Communicative language activities | C4: Reception | D4: Oral comprehension | E4: Overall oral comprehension | F4: C1 | G4: Can recognise a wide range of idiomatic expressions and colloquialisms, appreciating register shifts. | H4: 1
A5: 4 | B5: Communicative language activities | C5: Reception | D5: Oral comprehension | E5: Overall oral comprehension | F5: C1 | G5: Can follow extended discourse even when it is not clearly structured and when relationships are only implied and not signalled explicitly. | H5: 1
A6: 5 | B6: Communicative language activities | C6: Reception | D6: Oral comprehension | E6: Overall oral comprehension | F6: B2+ | G6: Can understand standard language or a familiar variety, live or broadcast, on both familiar and unfamiliar topics normally encountered in personal, social, academic or vocational life. Only extreme [auditory/visual] background noise, inadequate discourse structure and/or idiomatic usage influence the ability to understand. | H6: 1
A7: 6 | B7: Communicative language activities | C7: Reception | D7: Oral comprehension | E7: Overall oral comprehension | F7: B2 | G7: Can understand the main ideas of propositionally and linguistically complex discourse on both concrete and abstract topics delivered in standard language or a familiar variety, including technical discussions in their field of specialisation. | H7: 1
A8: 7 | B8: Communicative language activities | C8: Reception | D8: Oral comprehension | E8: Overall oral comprehension | F8: B2 | G8: Can follow extended discourse and complex lines of argument, provided the topic is reasonably familiar, and the direction of the argument is signposted by explicit markers. | H8: 1
A9: 8 | B9: Communicative language activities | C9: Reception | D9: Oral comprehension | E9: Overall oral comprehension | F9: B1+ | G9: Can understand straightforward factual information about common everyday or job-related topics, identifying both general messages and specific details, provided people articulate clearly in a generally familiar variety. | H9: 1
A10: 9 | B10: Communicative language activities | C10: Reception | D10: Oral comprehension | E10: Overall oral comprehension | F10: B1 | G10: Can understand the main points made in clear standard language or a familiar variety on familiar matters regularly encountered at work, school, leisure, etc., including short narratives. | H10: 1
A11: 10 | B11: Communicative language activities | C11: Reception | D11: Oral comprehension | E11: Overall oral comprehension | F11: A2+ | G11: Can understand enough to be able to meet needs of a concrete type, provided people articulate clearly and slowly. | H11: 1
A12: 11 | B12: Communicative language activities | C12: Reception | D12: Oral comprehension | E12: Overall oral comprehension | F12: A2 | G12: Can understand phrases and expressions related to areas of most immediate priority (e.g. very basic personal and family information, shopping, local geography, employment), provided people articulate clearly and slowly. | H12: 1
A13: 12 | B13: Communicative language activities | C13: Reception | D13: Oral comprehension | E13: Overall oral comprehension | F13: A1 | G13: Can follow language which is very slow and carefully articulated, with long pauses for them to assimilate meaning. | H13: 1
... A1833: 1832 | B1833: Signing competences | C1833: — | D1833: Pragmatic competence | E1833: Signing fluency | F1833: A1 | G1833: No descriptors available | H1833: 0

Sheet 対訳マスタ
A1: 区分 | B1: English（正準キー・原文verbatim） | C1: 日本語（作業訳） | D1: 公式訳（随伴版・日本語版2024） | E1: 一致 | F1: 備考
A2: 列見出し | B2: No | C2: 番号 | D2: 番号 | E2: =IF($C2=$D2,"○","≠") -> ○
A3: 列見出し | B3: CEFR Descriptor Scheme (updated) | C3: スキーム（記述文の大区分） | D3: CEFR能力記述文スキーム（更新版） | E3: =IF($C3=$D3,"○","≠") -> ≠
A4: 列見出し | B4: Mode of communication | C4: コミュニケーション・モード | D4: コミュニケーションのモード | E4: =IF($C4=$D4,"○","≠") -> ≠
A5: 列見出し | B5: Activity, strategy or competence | C5: 活動・方略・能力の種別 | D5: 活動・方略・能力 | E5: =IF($C5=$D5,"○","≠") -> ≠
A6: 列見出し | B6: Scale | C6: スケール（尺度＝適用範囲） | D6: 尺度 | E6: =IF($C6=$D6,"○","≠") -> ≠
A7: 列見出し | B7: Level | C7: レベル | D7: レベル | E7: =IF($C7=$D7,"○","≠") -> ○
A8: 列見出し | B8: Descriptor | C8: 記述文（Can-Do） | D8: 能力記述文 | E8: =IF($C8=$D8,"○","≠") -> ≠
A9: スキーム | B9: Communicative language activities | C9: コミュニケーション言語活動 | D9: コミュニケーション言語活動 | E9: =IF($C9=$D9,"○","≠") -> ○ | F9: 「何ができるか」の本体
A10: スキーム | B10: Communicative language strategies | C10: コミュニケーション言語方略 | D10: コミュニケーション方略 | E10: =IF($C10=$D10,"○","≠") -> ≠ | F10: 「戦略」とも訳される
A11: スキーム | B11: Communicative language competences | C11: コミュニケーション言語能力 | D11: 言語コミュニケーション能力 | E11: =IF($C11=$D11,"○","≠") -> ≠ | F11: 「どれくらいうまく」の物差し（言語・社会言語・語用）
A12: スキーム | B12: Plurilingual and pluricultural competence | C12: 複言語・複文化能力 | D12: 複言語能力と複文化能力 | E12: =IF($C12=$D12,"○","≠") -> ≠
A13: スキーム | B13: Signing competences | C13: 手話能力 | D13: 手話能力 | E13: =IF($C13=$D13,"○","≠") -> ○ | F13: 音声英語カタログの対象外
A14: モード | B14: Reception | C14: 受容 | D14: 受容 | E14: =IF($C14=$D14,"○","≠") -> ○ | F14: 聞く・読む
A15: モード | B15: Production | C15: 産出 | D15: 産出 | E15: =IF($C15=$D15,"○","≠") -> ○ | F15: 話す・書く
A16: モード | B16: Interaction | C16: 相互行為 | D16: やり取り | E16: =IF($C16=$D16,"○","≠") -> ≠ | F16: やりとり。提案書の用語に合わせた
A17: モード | B17: Mediation | C17: 仲介 | D17: 仲介 | E17: =IF($C17=$D17,"○","≠") -> ○ | F17: 橋渡し・言い換え・要約など
A18: 活動・方略・能力の種別 | B18: Oral comprehension | C18: 口頭理解（聞くこと） | D18: 聴解 | E18: =IF($C18=$D18,"○","≠") -> ≠
A19: 活動・方略・能力の種別 | B19: Audio-visual comprehension | C19: 視聴覚理解 | D19: 視聴覚による理解 | E19: =IF($C19=$D19,"○","≠") -> ≠
A20: 活動・方略・能力の種別 | B20: Reading comprehension | C20: 読解（読むこと） | D20: 読解 | E20: =IF($C20=$D20,"○","≠") -> ≠
A21: 活動・方略・能力の種別 | B21: Oral production | C21: 口頭産出（話すこと） | D21: 口頭での産出活動（話すこと） | E21: =IF($C21=$D21,"○","≠") -> ≠
A22: 活動・方略・能力の種別 | B22: Written production | C22: 記述産出（書くこと） | D22: 書く活動 | E22: =IF($C22=$D22,"○","≠") -> ≠
A23: 活動・方略・能力の種別 | B23: Oral interaction | C23: 口頭の相互行為 | D23: 口頭でのやり取り | E23: =IF($C23=$D23,"○","≠") -> ≠
A24: 活動・方略・能力の種別 | B24: Written interaction | C24: 筆記の相互行為 | D24: 文書によるやり取り | E24: =IF($C24=$D24,"○","≠") -> ≠
A25: 活動・方略・能力の種別 | B25: Online interaction | C25: オンラインの相互行為 | D25: オンラインでのやり取り | E25: =IF($C25=$D25,"○","≠") -> ≠
A26: 活動・方略・能力の種別 | B26: Mediating a text | C26: テキストの仲介 | D26: テクストの仲介 | E26: =IF($C26=$D26,"○","≠") -> ≠
A27: 活動・方略・能力の種別 | B27: Mediating concepts | C27: 概念の仲介 | D27: 概念/想念/思考の仲介 | E27: =IF($C27=$D27,"○","≠") -> ≠
A28: 活動・方略・能力の種別 | B28: Mediating communication | C28: コミュニケーションの仲介 | D28: コミュニケーションの仲介 | E28: =IF($C28=$D28,"○","≠") -> ○
A29: 活動・方略・能力の種別 | B29: Strategies to explain a new concept | C29: 新しい概念を説明する方略 | D29: 新概念説明の方略 | E29: =IF($C29=$D29,"○","≠") -> ≠
... A33: 活動・方略・能力の種別 | B33: Pragmatic competence | C33: 語用能力 | D33: 運用能力 | E33: =IF($C33=$D33,"○","≠") -> ≠
A34: レベル | B34: Pre-A1 | C34: Pre-A1 | D34: Pre-A1 | E34: =IF($C34=$D34,"○","≠") -> ○ | F34: A1未満の入門段階
A35: レベル | B35: A1 | C35: A1 | D35: A1 | E35: =IF($C35=$D35,"○","≠") -> ○
A36: レベル | B36: A2 | C36: A2 | D36: A2 | E36: =IF($C36=$D36,"○","≠") -> ○
A37: レベル | B37: A2+ | C37: A2+ | D37: A2+ | E37: =IF($C37=$D37,"○","≠") -> ○ | F37: プラスレベル＝同帯の上位
A38: レベル | B38: B1 | C38: B1 | D38: B1 | E38: =IF($C38=$D38,"○","≠") -> ○
A39: レベル | B39: B1+ | C39: B1+ | D39: B1+ | E39: =IF($C39=$D39,"○","≠") -> ○ | F39: プラスレベル
A40: レベル | B40: B2 | C40: B2 | D40: B2 | E40: =IF($C40=$D40,"○","≠") -> ○
A41: レベル | B41: B2+ | C41: B2+ | D41: B2+ | E41: =IF($C41=$D41,"○","≠") -> ○ | F41: プラスレベル
A42: レベル | B42: C1 | C42: C1 | D42: C1 | E42: =IF($C42=$D42,"○","≠") -> ○
A43: レベル | B43: C2 | C43: C2 | D43: C2 | E43: =IF($C43=$D43,"○","≠") -> ○
...

Sheet スケール別集計
A1: スキーム | B1: モード | C1: 活動・方略・能力の種別 | D1: スケール（作業訳） | E1: Scale（原文） | F1: Pre-A1 | G1: A1 | H1: A2 | I1: A2+ | J1: B1 | K1: B1+ | L1: B2 | M1: B2+ | N1: C1 | O1: C2 | P1: 計 | Q1: EN:Scheme | R1: EN:Mode | S1: EN:Activity
A2: =IFERROR(INDEX(対訳マスタ!$C$2:$C$136,MATCH($Q2,対訳マスタ!$B$2:$B$136,0)),$Q2) -> コミュニケーション言語活動 | B2: =IF($R2="—","—",IFERROR(INDEX(対訳マスタ!$C$2:$C$136,MATCH($R2,対訳マスタ!$B$2:$B$136,0)),$R2)) -> 受容 | C2: =IF($S2="—","—",IFERROR(INDEX(対訳マスタ!$C$2:$C$136,MATCH($S2,対訳マスタ!$B$2:$B$136,0)),$S2)) -> 口頭理解（聞くこと） | D2: =IFERROR(INDEX(対訳マスタ!$C$2:$C$136,MATCH($E2,対訳マスタ!$B$2:$B$136,0)),$E2) -> 口頭理解（総合） | E2: Overall oral comprehension | F2: =COUNTIFS(Data!$B$2:$B$1833,$Q2,Data!$C$2:$C$1833,$R2,Data!$D$2:$D$1833,$S2,Data!$E$2:$E$1833,$E2,Data!$F$2:$F$1833,F$1,Data!$H$2:$H$1833,1) -> 3 | G2: =COUNTIFS(Data!$B$2:$B$1833,$Q2,Data!$C$2:$C$1833,$R2,Data!$D$2:$D$1833,$S2,Data!$E$2:$E$1833,$E2,Data!$F$2:$F$1833,G$1,Data!$H$2:$H$1833,1) -> 2 | H2: =COUNTIFS(Data!$B$2:$B$1833,$Q2,Data!$C$2:$C$1833,$R2,Data!$D$2:$D$1833,$S2,Data!$E$2:$E$1833,$E2,Data!$F$2:$F$1833,H$1,Data!$H$2:$H$1833,1) -> 1 | I2: =COUNTIFS(Data!$B$2:$B$1833,$Q2,Data!$C$2:$C$1833,$R2,Data!$D$2:$D$1833,$S2,Data!$E$2:$E$1833,$E2,Data!$F$2:$F$1833,I$1,Data!$H$2:$H$1833,1) -> 1 | J2: =COUNTIFS(Data!$B$2:$B$1833,$Q2,Data!$C$2:$C$1833,$R2,Data!$D$2:$D$1833,$S2,Data!$E$2:$E$1833,$E2,Data!$F$2:$F$1833,J$1,Data!$H$2:$H$1833,1) -> 1 | K2: =COUNTIFS(Data!$B$2:$B$1833,$Q2,Data!$C$2:$C$1833,$R2,Data!$D$2:$D$1833,$S2,Data!$E$2:$E$1833,$E2,Data!$F$2:$F$1833,K$1,Data!$H$2:$H$1833,1) -> 1 | L2: =COUNTIFS(Data!$B$2:$B$1833,$Q2,Data!$C$2:$C$1833,$R2,Data!$D$2:$D$1833,$S2,Data!$E$2:$E$1833,$E2,Data!$F$2:$F$1833,L$1,Data!$H$2:$H$1833,1) -> 2 | M2: =COUNTIFS(Data!$B$2:$B$1833,$Q2,Data!$C$2:$C$1833,$R2,Data!$D$2:$D$1833,$S2,Data!$E$2:$E$1833,$E2,Data!$F$2:$F$1833,M$1,Data!$H$2:$H$1833,1) -> 1 | ... O2: =COUNTIFS(Data!$B$2:$B$1833,$Q2,Data!$C$2:$C$1833,$R2,Data!$D$2:$D$1833,$S2,Data!$E$2:$E$1833,$E2,Data!$F$2:$F$1833,O$1,Data!$H$2:$H$1833,1) -> 1 | P2: =SUM(F2:O2) -> 16 | Q2: Communicative language activities | R2: Reception | S2: Oral comprehension
A3: =IFERROR(INDEX(対訳マスタ!$C$2:$C$136,MATCH($Q3,対訳マスタ!$B$2:$B$136,0)),$Q3) -> コミュニケーション言語活動 | B3: =IF($R3="—","—",IFERROR(INDEX(対訳マスタ!$C$2:$C$136,MATCH($R3,対訳マスタ!$B$2:$B$136,0)),$R3)) -> 受容 | C3: =IF($S3="—","—",IFERROR(INDEX(対訳マスタ!$C$2:$C$136,MATCH($S3,対訳マスタ!$B$2:$B$136,0)),$S3)) -> 口頭理解（聞くこと） | D3: =IFERROR(INDEX(対訳マスタ!$C$2:$C$136,MATCH($E3,対訳マスタ!$B$2:$B$136,0)),$E3) -> 第三者どうしの会話の聞き取り | E3: Understanding conversation between other people | F3: =COUNTIFS(Data!$B$2:$B$1833,$Q3,Data!$C$2:$C$1833,$R3,Data!$D$2:$D$1833,$S3,Data!$E$2:$E$1833,$E3,Data!$F$2:$F$1833,F$1,Data!$H$2:$H$1833,1) -> 0 | G3: =COUNTIFS(Data!$B$2:$B$1833,$Q3,Data!$C$2:$C$1833,$R3,Data!$D$2:$D$1833,$S3,Data!$E$2:$E$1833,$E3,Data!$F$2:$F$1833,G$1,Data!$H$2:$H$1833,1) -> 2 | H3: =COUNTIFS(Data!$B$2:$B$1833,$Q3,Data!$C$2:$C$1833,$R3,Data!$D$2:$D$1833,$S3,Data!$E$2:$E$1833,$E3,Data!$F$2:$F$1833,H$1,Data!$H$2:$H$1833,1) -> 1 | I3: =COUNTIFS(Data!$B$2:$B$1833,$Q3,Data!$C$2:$C$1833,$R3,Data!$D$2:$D$1833,$S3,Data!$E$2:$E$1833,$E3,Data!$F$2:$F$1833,I$1,Data!$H$2:$H$1833,1) -> 2 | J3: =COUNTIFS(Data!$B$2:$B$1833,$Q3,Data!$C$2:$C$1833,$R3,Data!$D$2:$D$1833,$S3,Data!$E$2:$E$1833,$E3,Data!$F$2:$F$1833,J$1,Data!$H$2:$H$1833,1) -> 1 | K3: =COUNTIFS(Data!$B$2:$B$1833,$Q3,Data!$C$2:$C$1833,$R3,Data!$D$2:$D$1833,$S3,Data!$E$2:$E$1833,$E3,Data!$F$2:$F$1833,K$1,Data!$H$2:$H$1833,1) -> 1 | L3: =COUNTIFS(Data!$B$2:$B$1833,$Q3,Data!$C$2:$C$1833,$R3,Data!$D$2:$D$1833,$S3,Data!$E$2:$E$1833,$E3,Data!$F$2:$F$1833,L$1,Data!$H$2:$H$1833,1) -> 3 | M3: =COUNTIFS(Data!$B$2:$B$1833,$Q3,Data!$C$2:$C$1833,$R3,Data!$D$2:$D$1833,$S3,Data!$E$2:$E$1833,$E3,Data!$F$2:$F$1833,M$1,Data!$H$2:$H$1833,1) -> 1 | ... O3: =COUNTIFS(Data!$B$2:$B$1833,$Q3,Data!$C$2:$C$1833,$R3,Data!$D$2:$D$1833,$S3,Data!$E$2:$E$1833,$E3,Data!$F$2:$F$1833,O$1,Data!$H$2:$H$1833,1) -> 1 | P3: =SUM(F3:O3) -> 14 | Q3: Communicative language activities | R3: Reception | S3: Oral comprehension
A4: =IFERROR(INDEX(対訳マスタ!$C$2:$C$136,MATCH($Q4,対訳マスタ!$B$2:$B$136,0)),$Q4) -> コミュニケーション言語活動 | B4: =IF($R4="—","—",IFERROR(INDEX(対訳マスタ!$C$2:$C$136,MATCH($R4,対訳マスタ!$B$2:$B$136,0)),$R4)) -> 受容 | C4: =IF($S4="—","—",IFERROR(INDEX(対訳マスタ!$C$2:$C$136,MATCH($S4,対訳マスタ!$B$2:$B$136,0)),$S4)) -> 口頭理解（聞くこと） | D4: =IFERROR(INDEX(対訳マスタ!$C$2:$C$136,MATCH($E4,対訳マスタ!$B$2:$B$136,0)),$E4) -> 聴衆としての聞き取り（講演など） | E4: Understanding as a member of a live audience | F4: =COUNTIFS(Data!$B$2:$B$1833,$Q4,Data!$C$2:$C$1833,$R4,Data!$D$2:$D$1833,$S4,Data!$E$2:$E$1833,$E4,Data!$F$2:$F$1833,F$1,Data!$H$2:$H$1833,1) -> 0 | G4: =COUNTIFS(Data!$B$2:$B$1833,$Q4,Data!$C$2:$C$1833,$R4,Data!$D$2:$D$1833,$S4,Data!$E$2:$E$1833,$E4,Data!$F$2:$F$1833,G$1,Data!$H$2:$H$1833,1) -> 1 | H4: =COUNTIFS(Data!$B$2:$B$1833,$Q4,Data!$C$2:$C$1833,$R4,Data!$D$2:$D$1833,$S4,Data!$E$2:$E$1833,$E4,Data!$F$2:$F$1833,H$1,Data!$H$2:$H$1833,1) -> 2 | I4: =COUNTIFS(Data!$B$2:$B$1833,$Q4,Data!$C$2:$C$1833,$R4,Data!$D$2:$D$1833,$S4,Data!$E$2:$E$1833,$E4,Data!$F$2:$F$1833,I$1,Data!$H$2:$H$1833,1) -> 1 | J4: =COUNTIFS(Data!$B$2:$B$1833,$Q4,Data!$C$2:$C$1833,$R4,Data!$D$2:$D$1833,$S4,Data!$E$2:$E$1833,$E4,Data!$F$2:$F$1833,J$1,Data!$H$2:$H$1833,1) -> 3 | K4: =COUNTIFS(Data!$B$2:$B$1833,$Q4,Data!$C$2:$C$1833,$R4,Data!$D$2:$D$1833,$S4,Data!$E$2:$E$1833,$E4,Data!$F$2:$F$1833,K$1,Data!$H$2:$H$1833,1) -> 2 | L4: =COUNTIFS(Data!$B$2:$B$1833,$Q4,Data!$C$2:$C$1833,$R4,Data!$D$2:$D$1833,$S4,Data!$E$2:$E$1833,$E4,Data!$F$2:$F$1833,L$1,Data!$H$2:$H$1833,1) -> 3 | M4: =COUNTIFS(Data!$B$2:$B$1833,$Q4,Data!$C$2:$C$1833,$R4,Data!$D$2:$D$1833,$S4,Data!$E$2:$E$1833,$E4,Data!$F$2:$F$1833,M$1,Data!$H$2:$H$1833,1) -> 2 | ... O4: =COUNTIFS(Data!$B$2:$B$1833,$Q4,Data!$C$2:$C$1833,$R4,Data!$D$2:$D$1833,$S4,Data!$E$2:$E$1833,$E4,Data!$F$2:$F$1833,O$1,Data!$H$2:$H$1833,1) -> 3 | P4: =SUM(F4:O4) -> 18 | Q4: Communicative language activities | R4: Reception | S4: Oral comprehension
A5: =IFERROR(INDEX(対訳マスタ!$C$2:$C$136,MATCH($Q5,対訳マスタ!$B$2:$B$136,0)),$Q5) -> コミュニケーション言語活動 | B5: =IF($R5="—","—",IFERROR(INDEX(対訳マスタ!$C$2:$C$136,MATCH($R5,対訳マスタ!$B$2:$B$136,0)),$R5)) -> 受容 | C5: =IF($S5="—","—",IFERROR(INDEX(対訳マスタ!$C$2:$C$136,MATCH($S5,対訳マスタ!$B$2:$B$136,0)),$S5)) -> 口頭理解（聞くこと） | D5: =IFERROR(INDEX(対訳マスタ!$C$2:$C$136,MATCH($E5,対訳マスタ!$B$2:$B$136,0)),$E5) -> アナウンス・指示の聞き取り | E5: Understanding announcements and instructions | F5: =COUNTIFS(Data!$B$2:$B$1833,$Q5,Data!$C$2:$C$1833,$R5,Data!$D$2:$D$1833,$S5,Data!$E$2:$E$1833,$E5,Data!$F$2:$F$1833,F$1,Data!$H$2:$H$1833,1) -> 1 | G5: =COUNTIFS(Data!$B$2:$B$1833,$Q5,Data!$C$2:$C$1833,$R5,Data!$D$2:$D$1833,$S5,Data!$E$2:$E$1833,$E5,Data!$F$2:$F$1833,G$1,Data!$H$2:$H$1833,1) -> 3 | H5: =COUNTIFS(Data!$B$2:$B$1833,$Q5,Data!$C$2:$C$1833,$R5,Data!$D$2:$D$1833,$S5,Data!$E$2:$E$1833,$E5,Data!$F$2:$F$1833,H$1,Data!$H$2:$H$1833,1) -> 3 | I5: =COUNTIFS(Data!$B$2:$B$1833,$Q5,Data!$C$2:$C$1833,$R5,Data!$D$2:$D$1833,$S5,Data!$E$2:$E$1833,$E5,Data!$F$2:$F$1833,I$1,Data!$H$2:$H$1833,1) -> 2 | J5: =COUNTIFS(Data!$B$2:$B$1833,$Q5,Data!$C$2:$C$1833,$R5,Data!$D$2:$D$1833,$S5,Data!$E$2:$E$1833,$E5,Data!$F$2:$F$1833,J$1,Data!$H$2:$H$1833,1) -> 3 | K5: =COUNTIFS(Data!$B$2:$B$1833,$Q5,Data!$C$2:$C$1833,$R5,Data!$D$2:$D$1833,$S5,Data!$E$2:$E$1833,$E5,Data!$F$2:$F$1833,K$1,Data!$H$2:$H$1833,1) -> 0 | L5: =COUNTIFS(Data!$B$2:$B$1833,$Q5,Data!$C$2:$C$1833,$R5,Data!$D$2:$D$1833,$S5,Data!$E$2:$E$1833,$E5,Data!$F$2:$F$1833,L$1,Data!$H$2:$H$1833,1) -> 2 | M5: =COUNTIFS(Data!$B$2:$B$1833,$Q5,Data!$C$2:$C$1833,$R5,Data!$D$2:$D$1833,$S5,Data!$E$2:$E$1833,$E5,Data!$F$2:$F$1833,M$1,Data!$H$2:$H$1833,1) -> 0 | ... O5: =COUNTIFS(Data!$B$2:$B$1833,$Q5,Data!$C$2:$C$1833,$R5,Data!$D$2:$D$1833,$S5,Data!$E$2:$E$1833,$E5,Data!$F$2:$F$1833,O$1,Data!$H$2:$H$1833,1) -> 0 | P5: =SUM(F5:O5) -> 16 | Q5: Communicative language activities | R5: Reception | S5: Oral comprehension
A6: =IFERROR(INDEX(対訳マスタ!$C$2:$C$136,MATCH($Q6,対訳マスタ!$B$2:$B$136,0)),$Q6) -> コミュニケーション言語活動 | B6: =IF($R6="—","—",IFERROR(INDEX(対訳マスタ!$C$2:$C$136,MATCH($R6,対訳マスタ!$B$2:$B$136,0)),$R6)) -> 受容 | C6: =IF($S6="—","—",IFERROR(INDEX(対訳マスタ!$C$2:$C$136,MATCH($S6,対訳マスタ!$B$2:$B$136,0)),$S6)) -> 口頭理解（聞くこと） | D6: =IFERROR(INDEX(対訳マスタ!$C$2:$C$136,MATCH($E6,対訳マスタ!$B$2:$B$136,0)),$E6) -> 音声メディア・録音の聞き取り | E6: Understanding audio (or signed) media and recordings | F6: =COUNTIFS(Data!$B$2:$B$1833,$Q6,Data!$C$2:$C$1833,$R6,Data!$D$2:$D$1833,$S6,Data!$E$2:$E$1833,$E6,Data!$F$2:$F$1833,F$1,Data!$H$2:$H$1833,1) -> 1 | G6: =COUNTIFS(Data!$B$2:$B$1833,$Q6,Data!$C$2:$C$1833,$R6,Data!$D$2:$D$1833,$S6,Data!$E$2:$E$1833,$E6,Data!$F$2:$F$1833,G$1,Data!$H$2:$H$1833,1) -> 1 | H6: =COUNTIFS(Data!$B$2:$B$1833,$Q6,Data!$C$2:$C$1833,$R6,Data!$D$2:$D$1833,$S6,Data!$E$2:$E$1833,$E6,Data!$F$2:$F$1833,H$1,Data!$H$2:$H$1833,1) -> 3 | I6: =COUNTIFS(Data!$B$2:$B$1833,$Q6,Data!$C$2:$C$1833,$R6,Data!$D$2:$D$1833,$S6,Data!$E$2:$E$1833,$E6,Data!$F$2:$F$1833,I$1,Data!$H$2:$H$1833,1) -> 2 | J6: =COUNTIFS(Data!$B$2:$B$1833,$Q6,Data!$C$2:$C$1833,$R6,Data!$D$2:$D$1833,$S6,Data!$E$2:$E$1833,$E6,Data!$F$2:$F$1833,J$1,Data!$H$2:$H$1833,1) -> 2 | K6: =COUNTIFS(Data!$B$2:$B$1833,$Q6,Data!$C$2:$C$1833,$R6,Data!$D$2:$D$1833,$S6,Data!$E$2:$E$1833,$E6,Data!$F$2:$F$1833,K$1,Data!$H$2:$H$1833,1) -> 1 | L6: =COUNTIFS(Data!$B$2:$B$1833,$Q6,Data!$C$2:$C$1833,$R6,Data!$D$2:$D$1833,$S6,Data!$E$2:$E$1833,$E6,Data!$F$2:$F$1833,L$1,Data!$H$2:$H$1833,1) -> 1 | M6: =COUNTIFS(Data!$B$2:$B$1833,$Q6,Data!$C$2:$C$1833,$R6,Data!$D$2:$D$1833,$S6,Data!$E$2:$E$1833,$E6,Data!$F$2:$F$1833,M$1,Data!$H$2:$H$1833,1) -> 1 | ... O6: =COUNTIFS(Data!$B$2:$B$1833,$Q6,Data!$C$2:$C$1833,$R6,Data!$D$2:$D$1833,$S6,Data!$E$2:$E$1833,$E6,Data!$F$2:$F$1833,O$1,Data!$H$2:$H$1833,1) -> 0 | P6: =SUM(F6:O6) -> 13 | Q6: Communicative language activities | R6: Reception | S6: Oral comprehension
A7: =IFERROR(INDEX(対訳マスタ!$C$2:$C$136,MATCH($Q7,対訳マスタ!$B$2:$B$136,0)),$Q7) -> コミュニケーション言語活動 | B7: =IF($R7="—","—",IFERROR(INDEX(対訳マスタ!$C$2:$C$136,MATCH($R7,対訳マスタ!$B$2:$B$136,0)),$R7)) -> 受容 | C7: =IF($S7="—","—",IFERROR(INDEX(対訳マスタ!$C$2:$C$136,MATCH($S7,対訳マスタ!$B$2:$B$136,0)),$S7)) -> 視聴覚理解 | D7: =IFERROR(INDEX(対訳マスタ!$C$2:$C$136,MATCH($E7,対訳マスタ!$B$2:$B$136,0)),$E7) -> テレビ・映画・動画の視聴 | E7: Watching TV, film and video | F7: =COUNTIFS(Data!$B$2:$B$1833,$Q7,Data!$C$2:$C$1833,$R7,Data!$D$2:$D$1833,$S7,Data!$E$2:$E$1833,$E7,Data!$F$2:$F$1833,F$1,Data!$H$2:$H$1833,1) -> 1 | G7: =COUNTIFS(Data!$B$2:$B$1833,$Q7,Data!$C$2:$C$1833,$R7,Data!$D$2:$D$1833,$S7,Data!$E$2:$E$1833,$E7,Data!$F$2:$F$1833,G$1,Data!$H$2:$H$1833,1) -> 1 | H7: =COUNTIFS(Data!$B$2:$B$1833,$Q7,Data!$C$2:$C$1833,$R7,Data!$D$2:$D$1833,$S7,Data!$E$2:$E$1833,$E7,Data!$F$2:$F$1833,H$1,Data!$H$2:$H$1833,1) -> 1 | I7: =COUNTIFS(Data!$B$2:$B$1833,$Q7,Data!$C$2:$C$1833,$R7,Data!$D$2:$D$1833,$S7,Data!$E$2:$E$1833,$E7,Data!$F$2:$F$1833,I$1,Data!$H$2:$H$1833,1) -> 2 | J7: =COUNTIFS(Data!$B$2:$B$1833,$Q7,Data!$C$2:$C$1833,$R7,Data!$D$2:$D$1833,$S7,Data!$E$2:$E$1833,$E7,Data!$F$2:$F$1833,J$1,Data!$H$2:$H$1833,1) -> 2 | K7: =COUNTIFS(Data!$B$2:$B$1833,$Q7,Data!$C$2:$C$1833,$R7,Data!$D$2:$D$1833,$S7,Data!$E$2:$E$1833,$E7,Data!$F$2:$F$1833,K$1,Data!$H$2:$H$1833,1) -> 1 | L7: =COUNTIFS(Data!$B$2:$B$1833,$Q7,Data!$C$2:$C$1833,$R7,Data!$D$2:$D$1833,$S7,Data!$E$2:$E$1833,$E7,Data!$F$2:$F$1833,L$1,Data!$H$2:$H$1833,1) -> 2 | M7: =COUNTIFS(Data!$B$2:$B$1833,$Q7,Data!$C$2:$C$1833,$R7,Data!$D$2:$D$1833,$S7,Data!$E$2:$E$1833,$E7,Data!$F$2:$F$1833,M$1,Data!$H$2:$H$1833,1) -> 1 | ... O7: =COUNTIFS(Data!$B$2:$B$1833,$Q7,Data!$C$2:$C$1833,$R7,Data!$D$2:$D$1833,$S7,Data!$E$2:$E$1833,$E7,Data!$F$2:$F$1833,O$1,Data!$H$2:$H$1833,1) -> 0 | P7: =SUM(F7:O7) -> 14 | Q7: Communicative language activities | R7: Reception | S7: Audio-visual comprehension
